Workbook

Sheet Dashboard

Sheet Raw Data
A1: Ticket_ID | B1: Patient_ID | C1: Visit_ID | D1: Patient_Age | E1: Gender | F1: Country | G1: Location | H1: Facility_Type | I1: Facility_Name | J1: Department | K1: Ticket_Channel | L1: Issue_Category | M1: Issue_Subcategory | N1: Ticket_Description | O1: Created_Date | P1: First_Response_Time | Q1: Resolution_Time | R1: Resolved_Date | S1: Status | T1: Priority | U1: Escalation_Level | V1: Assigned_To | W1: Resolution_Type | X1: Patient_Satisfaction | Y1: Complaint_Flag | Z1: Feedback_Comment | AA1: Cost_Estimate_USD | AB1: Refund_Required
A2: tk_1000 | B2: P-204 | C2: V-7912 | D2: 4 | E2: Female | F2: Lebanon | G2: Beirut | H2: Clinic | I2: Al Noor Hosp. | J2: Reception | K2: WhatsApp | L2: Technical | M2: System down | N2: need help | O2: 26/02/2025 | P2: 45 | Q2: 2h | S2: Pending | T2: High | U2: 1 | V2: Lina | W2: Duplicate | X2: 1 | Y2: Yes | Z2: bad experience | AA2: ~30 | AB2: Yes
A3: 1001 | C3: V-6925 | D3: 9 | E3: Female | F3: Iraq | G3: Basra | H3: Mobile Unit | I3: Al Noor Hosp. | J3: Pharmacy | K3: Phone | L3: Admin | M3: Prescription issue | N3: waiting too long | O3: 04-27-25 | P3: 45 | Q3: 5 hours | R3: 05/04/2025 | S3: resloved | T3: High | U3: 0 | V3: Omar | W3: Referred | X3: 2 | Y3: N | Z3: good service | AA3: ~30 | AB3: No
A4: 1002 | C4: V-2084 | D4: ~30 | E4: m | F4: Jordan | G4: Irbid | H4: Clinic | I4: HealthPlus | J4: Lab | K4: Email | L4: Inquiry | M4: Prescription issue | N4: waiting too long | O4: 2025-02-05 | P4: 45 | Q4: 48 | S4: Pending | T4: Medium | U4: 1 | W4: Dropped | X4: 1 | Y4: Yes | Z4: good service | AA4: 10 | AB4: Yes
A5: 1003 | D5: 71 | E5: Male | F5: Jordan | G5: Irbid | H5: Mobile Unit | I5: Care Clinic | J5: ER | K5: Walk-in | L5: Admin | M5: Long wait time | N5: الخدمة سيئة | O5: 2025-04-27 | P5: 45 | Q5: 48 | R5: 02-15-25 | S5: pendng | T5: High | U5: Level 1 | V5: Lina | W5: Referred | X5: 3 | Y5: No | Z5: تأخير في الخدمة | AA5: 100 USD | AB5: Yes
A6: TCK-1004 | B6: P-159 | C6: V-2290 | D6: 63 | E6: fem | F6: Iraq | G6: Basra | H6: Clinic | I6: Alnoor Hospital | J6: Lab | K6: Web | L6: Inquiry | M6: Prescription issue | N6: waiting too long | O6: 05-16-25 | P6: 2 hours | Q6: 5 hours | R6: 05-19-25 | S6: resloved | T6: High | U6: 3 | V6: Maya | W6: Dropped | X6: 5 | Y6: N | AA6: 10 | AB6: Yes
A7: TCK-1005 | B7: P-172 | C7: V-4750 | D7: unknown | E7: Male | F7: Jordan | G7: Amman | H7: Clinic | I7: Care Clinic | J7: Lab | K7: WhatsApp | L7: Technical | M7: Long wait time | N7: waiting too long | O7: 05-27-25 | P7: 2 hours | Q7: 5 hours | R7: 02/05/2025 | S7: Open | T7: Low | U7: 3 | V7: Maya | W7: Dropped | X7: 4 | Y7: N | Z7: bad experience | AA7: 10 | AB7: Yes
A8: TCK-1006 | D8: unknown | E8: F | F8: Lebanon | G8: Saida | H8: Clinic | I8: Al Noor Hosp. | J8: Lab | K8: Web | L8: Complaint | M8: Billing error | N8: waiting too long | O8: 06-16-25 | P8: 30 min | Q8: 2h | S8: Escalated | T8: Critical | U8: 1 | V8: John | W8: Solved | X8: 2 | Y8: N | Z8: bad experience | AA8: 10 | AB8: No
A9: TCK-1007 | B9: P-403 | C9: V-1958 | D9: 41 | E9: Male | F9: Iraq | G9: Basra | H9: Pharmacy | I9: Alnoor Hospital | J9: ER | K9: Web | L9: Complaint | M9: Long wait time | O9: 01-18-25 | P9: 30 min | Q9: 5 hours | R9: 2025-04-14 | S9: Resolved | T9: Low | U9: Level 1 | V9: Sara | W9: Dropped | X9: good | Z9: bad experience | AA9: 100 USD | AB9: No
A10: TCK-1008 | D10: 10 | E10: F | F10: Iraq | G10: Baghdad | H10: Hospital | I10: Al Noor Hosp. | J10: Reception | K10: WhatsApp | L10: Technical | M10: Prescription issue | N10: need help | O10: 03/02/2025 | P10: 30 min | Q10: 5 hours | R10: 05/04/2025 | S10: Escalated | T10: High | U10: Level 1 | W10: Solved | X10: good | Z10: مشكلة في الفاتورة | AA10: 50 | AB10: Yes
A11: 1009 | B11: P-719 | C11: V-6617 | D11: ~30 | E11: m | F11: Jordan | G11: Zarqa | H11: Pharmacy | I11: Care Clinic | J11: ER | K11: Phone | L11: Admin | M11: Prescription issue | N11: waiting too long | O11: 2025-01-12 | P11: 45 | Q11: 5 hours | R11: 13/06/2025 | S11: resloved | T11: Critical | U11: Level 1 | V11: John | W11: Solved | X11: 1 | Y11: Yes | AA11: 20 | AB11: Yes
A12: 1010 | B12: P-473 | C12: V-6862 | D12: 88 | E12: Male | F12: Iraq | G12: Mosul | H12: Mobile Unit | I12: HealthPlus | J12: Reception | K12: WhatsApp | L12: Inquiry | M12: Long wait time | O12: 15/02/2025 | P12: 30 min | Q12: 5 hours | R12: 27/03/2025 | S12: Pending | T12: Medium | U12: 0 | V12: John | W12: Solved | X12: bad | Y12: N | Z12: good service | AA12: 20 | AB12: Yes
A13: tk_1011 | D13: unknown | E13: m | F13: Egypt | G13: Giza | H13: Pharmacy | I13: Care Clinic | J13: ER | K13: Phone | L13: Medical | M13: Long wait time | N13: need help | O13: 29/05/2025 | P13: 30 min | Q13: 2h | S13: resloved | T13: High | U13: 3 | W13: Solved | X13: 4 | Z13: good service | AA13: 20 | AB13: No
A14: 1012 | C14: V-6143 | D14: ~30 | E14: m | F14: Lebanon | G14: Saida | H14: Pharmacy | I14: Care Clinic | J14: Lab | K14: Walk-in | L14: Technical | M14: Long wait time | N14: تأخير في الخدمة | O14: 19/02/2025 | P14: 2 hours | Q14: 5 hours | S14: Escalated | T14: Low | U14: 2 | V14: Hassan | W14: Referred | X14: 4 | AA14: 100 USD | AB14: No
A15: tk_1013 | D15: 12 | E15: m | F15: Egypt | G15: Giza | H15: Clinic | I15: Alnoor Hospital | J15: Pharmacy | K15: Phone | L15: Complaint | M15: Long wait time | N15: need help | O15: 05-02-25 | P15: 30 min | Q15: -1 | R15: 04-17-25 | S15: resloved | T15: Critical | U15: 3 | V15: John | W15: Referred | X15: 2 | Y15: Yes | Z15: bad experience | AA15: 10 | AB15: No
A16: 1014 | D16: ~30 | E16: fem | F16: Jordan | G16: Amman | H16: Pharmacy | I16: HealthPlus | J16: Pharmacy | K16: Email | L16: Admin | M16: Prescription issue | N16: waiting too long | O16: 03-05-25 | P16: 45 | Q16: 48 | R16: 05-05-25 | S16: Pending | T16: Critical | U16: 0 | V16: Hassan | W16: Referred | X16: 3 | Y16: Y | Z16: good service | AA16: 50 | AB16: Yes
A17: TCK-1015 | D17: 54 | E17: Female | F17: Jordan | G17: Amman | H17: Pharmacy | I17: HealthPlus | J17: Reception | K17: Phone | L17: Technical | M17: System down | O17: 2025-05-03 | P17: 45 | Q17: 1 day | R17: 10/04/2025 | S17: Escalated | T17: Medium | U17: 2 | V17: John | W17: Dropped | X17: 1 | Y17: N | Z17: bad experience | AA17: 50 | AB17: No
A18: tk_1016 | B18: P-677 | D18: unknown | E18: Female | F18: Jordan | G18: Zarqa | H18: Hospital | I18: Care Clinic | J18: Lab | K18: Walk-in | L18: Inquiry | M18: System down | N18: الدكتور لم يحضر | O18: 25/03/2025 | P18: 2 hours | Q18: 1 day | R18: 18/04/2025 | S18: Escalated | T18: Low | U18: Level 1 | V18: Ali | W18: Duplicate | X18: 2 | Y18: Yes | Z18: تأخير في الخدمة | AA18: 10 | AB18: Yes
A19: TCK-1017 | B19: P-584 | D19: unknown | E19: m | F19: Jordan | G19: Amman | H19: Clinic | I19: Al Noor Hosp. | J19: Pharmacy | K19: Walk-in | L19: Complaint | M19: Wrong appointment | N19: تأخير في الخدمة | O19: 07/01/2025 | P19: 2 hours | Q19: -1 | R19: 2025-02-20 | S19: Open | T19: High | U19: Level 1 | V19: Sara | W19: Solved | X19: 3 | Z19: bad experience | AA19: ~30 | AB19: No
A20: 1018 | D20: ~30 | E20: fem | F20: Lebanon | G20: Tripoli | H20: Mobile Unit | I20: HealthPlus | J20: Lab | K20: Email | L20: Technical | M20: Prescription issue | O20: 2025-03-24 | P20: 30 min | Q20: 1 day | S20: Resolved | T20: Critical | U20: 2 | V20: Ali | W20: Dropped | X20: bad | Y20: Y | Z20: good service | AA20: 20 | AB20: No
A21: tk_1019 | B21: P-110 | C21: V-2402 | D21: unknown | E21: fem | F21: Jordan | G21: Zarqa | H21: Clinic | I21: HealthPlus | J21: Lab | K21: Email | L21: Complaint | M21: Billing error | N21: billing not clear | O21: 2025-03-17 | P21: 2 hours | Q21: 5 hours | S21: Escalated | T21: High | U21: 3 | W21: Duplicate | X21: 3 | Y21: N | AA21: 50 | AB21: No
A22: tk_1020 | B22: P-648 | C22: V-4138 | D22: unknown | E22: fem | F22: Iraq | G22: Baghdad | H22: Mobile Unit | I22: Al Noor Hosp. | J22: Pharmacy | K22: Walk-in | L22: Inquiry | M22: Prescription issue | N22: need help | O22: 15/02/2025 | P22: 30 min | Q22: 48 | R22: 02/02/2025 | S22: Open | T22: High | U22: 1 | V22: Fatima | W22: Solved | X22: bad | Y22: Yes | Z22: good service | AA22: 100 USD | AB22: No
A23: 1021 | C23: V-2869 | D23: unknown | E23: Male | F23: Egypt | G23: Giza | H23: Hospital | I23: Alnoor Hospital | J23: Pharmacy | K23: Web | L23: Medical | M23: Billing error | N23: billing not clear | O23: 2025-03-05 | P23: 2 hours | Q23: 48 | R23: 06-02-25 | S23: pendng | T23: Critical | U23: 3 | V23: Fatima | W23: Duplicate | X23: bad | Z23: good service | AA23: ~30 | AB23: No
A24: TCK-1022 | B24: P-345 | C24: V-2229 | D24: unknown | E24: F | F24: Lebanon | G24: Beirut | H24: Pharmacy | I24: Care Clinic | J24: ER | K24: WhatsApp | L24: Medical | M24: Missing record | N24: need help | O24: 03-14-25 | P24: 2 hours | Q24: 2h | S24: pendng | T24: Medium | U24: 3 | V24: Sara | W24: Referred | X24: good | Y24: No | Z24: good service | AA24: 50 | AB24: Yes
A25: TCK-1023 | D25: ~30 | E25: F | F25: Lebanon | G25: Beirut | H25: Pharmacy | I25: Al Noor Hosp. | J25: Reception | K25: Phone | L25: Admin | M25: Missing record | N25: billing not clear | O25: 03-24-25 | P25: 45 | Q25: 2h | R25: 2025-01-24 | S25: pendng | T25: High | U25: Level 1 | V25: Ali | W25: Referred | X25: 4 | Z25: مشكلة في الفاتورة | AA25: ~30 | AB25: No
A26: 1024 | C26: V-6260 | D26: unknown | E26: F | F26: Jordan | G26: Irbid | H26: Pharmacy | I26: Care Clinic | J26: Lab | K26: Web | L26: Complaint | M26: System down | O26: 23/01/2025 | P26: 45 | Q26: 1 day | R26: 30/01/2025 | S26: resloved | T26: Critical | U26: 3 | V26: Ali | W26: Referred | X26: 5 | Y26: Y | Z26: تأخير في الخدمة | AA26: 100 USD | AB26: No
A27: 1025 | C27: V-2989 | D27: ~30 | E27: Female | F27: Egypt | G27: Cairo | H27: Clinic | I27: Care Clinic | J27: Reception | K27: Phone | L27: Technical | M27: System down | N27: billing not clear | O27: 2025-01-24 | P27: 30 min | Q27: -1 | R27: 01-31-25 | S27: Escalated | T27: High | U27: Level 1 | V27: Hassan | W27: Dropped | X27: bad | Y27: N | AA27: ~30 | AB27: Yes
A28: TCK-1026 | D28: unknown | E28: m | F28: Egypt | G28: Alexandria | H28: Pharmacy | I28: Alnoor Hospital | J28: Lab | K28: Web | L28: Admin | M28: Prescription issue | O28: 03-27-25 | P28: 2 hours | Q28: -1 | R28: 2025-03-24 | S28: Resolved | T28: Critical | U28: 1 | V28: John | W28: Solved | X28: 3 | Y28: N | Z28: bad experience | AA28: ~30 | AB28: No
A29: 1027 | C29: V-1251 | D29: ~30 | E29: Female | F29: Jordan | G29: Zarqa | H29: Hospital | I29: HealthPlus | J29: Billing | K29: Walk-in | L29: Technical | M29: Missing record | N29: need help | O29: 04-12-25 | P29: 30 min | Q29: 1 day | S29: Pending | T29: Critical | U29: Level 1 | V29: Ali | W29: Solved | X29: 2 | Y29: Y | Z29: good service | AA29: 20 | AB29: Yes
A30: TCK-1028 | D30: unknown | E30: F | F30: Egypt | G30: Cairo | H30: Clinic | I30: Alnoor Hospital | J30: Reception | K30: Email | L30: Technical | M30: Missing record | O30: 2025-02-16 | P30: 1h | Q30: 2h | R30: 06/06/2025 | S30: Escalated | T30: Medium | U30: 1 | V30: Fatima | W30: Duplicate | X30: 4 | Y30: Y | AA30: 10 | AB30: No
A31: tk_1029 | D31: 39 | E31: F | F31: Iraq | G31: Mosul | H31: Pharmacy | I31: Al Noor Hosp. | J31: Pharmacy | K31: Email | L31: Technical | M31: Prescription issue | N31: waiting too long | O31: 28/05/2025 | P31: 45 | Q31: 2h | S31: Open | T31: Low | U31: Level 1 | V31: Fatima | W31: Duplicate | X31: bad | Y31: No | AA31: 100 USD | AB31: No
A32: tk_1030 | B32: P-199 | D32: ~30 | E32: m | F32: Jordan | G32: Irbid | H32: Clinic | I32: Al Noor Hosp. | J32: Billing | K32: Walk-in | L32: Admin | M32: Long wait time | N32: الدكتور لم يحضر | O32: 2025-02-21 | P32: 45 | Q32: 48 | R32: 09/05/2025 | S32: Pending | T32: Critical | U32: 2 | V32: Maya | W32: Solved | X32: 4 | Y32: Yes | Z32: bad experience | AA32: 20 | AB32: Yes
A33: 1031 | B33: P-649 | D33: ~30 | E33: m | F33: Egypt | G33: Alexandria | H33: Pharmacy | I33: Care Clinic | J33: ER | K33: WhatsApp | L33: Admin | M33: Billing error | N33: waiting too long | O33: 06-08-25 | P33: 45 | Q33: 48 | R33: 02-26-25 | S33: resloved | T33: Critical | U33: 2 | V33: John | W33: Solved | X33: 2 | Y33: Yes | Z33: good service | AA33: 10 | AB33: No
A34: 1032 | D34: 84 | E34: F | F34: Egypt | G34: Cairo | H34: Pharmacy | I34: Care Clinic | J34: ER | K34: Walk-in | L34: Inquiry | M34: System down | N34: need help | O34: 2025-04-24 | P34: 45 | Q34: 2h | S34: Open | T34: Critical | U34: 2 | V34: Lina | W34: Solved | X34: bad | Y34: N | Z34: الدكتور لم يحضر | AA34: 10 | AB34: Yes
A35: TCK-1033 | B35: P-949 | C35: V-4538 | D35: 43 | E35: fem | F35: Lebanon | G35: Beirut | H35: Hospital | I35: Care Clinic | J35: Pharmacy | K35: WhatsApp | L35: Technical | M35: Prescription issue | N35: need help | O35: 2025-02-14 | P35: 30 min | Q35: 5 hours | R35: 04/01/2025 | S35: Resolved | T35: High | U35: 0 | V35: Omar | W35: Duplicate | X35: 1 | Y35: No | Z35: bad experience | AA35: ~30 | AB35: Yes
A36: tk_1034 | B36: P-326 | D36: ~30 | E36: Male | F36: Lebanon | G36: Saida | H36: Hospital | I36: HealthPlus | J36: Lab | K36: Email | L36: Complaint | M36: System down | N36: billing not clear | O36: 2025-04-24 | P36: 30 min | Q36: 1 day | R36: 2025-06-05 | S36: Closed | T36: High | U36: Level 1 | W36: Duplicate | X36: 4 | Z36: تأخير في الخدمة | AA36: 100 USD | AB36: No
A37: 1035 | B37: P-562 | D37: unknown | E37: F | F37: Egypt | G37: Alexandria | H37: Hospital | I37: Care Clinic | J37: Lab | K37: Walk-in | L37: Medical | M37: Prescription issue | N37: waiting too long | O37: 02-09-25 | P37: 2 hours | Q37: 2h | R37: 2025-01-24 | S37: Escalated | T37: Low | U37: 2 | V37: Omar | W37: Solved | X37: 5 | Z37: bad experience | AA37: 100 USD | AB37: No
A38: tk_1036 | C38: V-2697 | D38: ~30 | E38: F | F38: Lebanon | G38: Saida | H38: Clinic | I38: Al Noor Hosp. | J38: Billing | K38: Web | L38: Medical | M38: Billing error | O38: 03-13-25 | P38: 1h | Q38: -1 | R38: 05-24-25 | S38: Resolved | T38: High | U38: 0 | V38: Omar | W38: Duplicate | X38: good | Y38: Y | AA38: 50 | AB38: No
A39: TCK-1037 | B39: P-858 | C39: V-2503 | D39: unknown | E39: F | F39: Lebanon | G39: Bekaa | H39: Mobile Unit | I39: Alnoor Hospital | J39: Billing | K39: Walk-in | L39: Medical | M39: Wrong appointment | N39: الدكتور لم يحضر | O39: 2025-06-02 | P39: 30 min | Q39: 5 hours | R39: 02-10-25 | S39: resloved | T39: Low | U39: 2 | V39: Fatima | W39: Dropped | X39: 4 | Z39: good service | AA39: ~30 | AB39: No
A40: 1038 | D40: 6 | E40: F | F40: Iraq | G40: Baghdad | H40: Hospital | I40: Al Noor Hosp. | J40: Pharmacy | K40: Walk-in | L40: Inquiry | M40: Long wait time | N40: billing not clear | O40: 07/03/2025 | P40: 45 | Q40: 2h | S40: Closed | T40: Medium | U40: 3 | W40: Referred | X40: 5 | Z40: good service | AA40: 50 | AB40: Yes
...

Sheet Clean Data
A1: Ticket_ID | B1: Ticket_ID_Clean | C1: Patient_ID | D1: Visit_ID | E1: Patient_Age | F1: Patient_Age_Clean | G1: Gender | H1: Country | I1: Location | J1: Facility_Type | K1: Facility_Name | L1: Facility_Name_Clean | M1: Department | N1: Ticket_Channel | O1: Issue_Category | P1: Issue_Subcategory | Q1: Ticket_Description | R1: Ticket_Description - Clean | S1: Created_Date | T1: Create_Date_Format | U1: Created_Date_ISO | V1: First_Response_Time | W1: First_Response_Time - Clean | X1: Resolution_Time | Y1: Resolution_Time - Clean | Z1: Resolved_Date | AA1: Resolved_Date_Format | AB1: Resolved_Date_ISO | AC1: Status | AD1: Priority | AE1: Escalation_Level | AF1: Escalation_Level - Clean | AG1: Assigned_To | AH1: Resolution_Type | AI1: Patient_Satisfaction | AJ1: Patient_Satisfaction_Categories | AK1: Complaint_Flag | AL1: Feedback_Comment | AM1: Feedback_Comment_Clean | AN1: Cost_Estimate_USD | AO1: Cost_Estimate_USD - Clean | AP1: Refund_Required | AQ1: Resolved_Date_Status_Check | AR1: Resolution_Time_Status_Check | AS1: Status_Resolution_Type_Check | AT1: Priority_Escaltion_Level_Check | AU1: Ticket_Status_Technician_Assignment_Check | AV1: Invalid Date Order | AW1: Resolution_Time_Analysis | AX1: Age_Groups | AY1: First_Response_Groups | AZ1: Resolution_Time_Groups | BA1: Cost_Estimate_Groups
A2: tk_1000 | B2: TCK-1000 | C2: P-204 | D2: V-7912 | E2: 4 | F2: 4 | G2: Female | H2: Lebanon | I2: Beirut | J2: Clinic | K2: Al Noor Hosp. | L2: Al Noor Hospital | M2: Reception | N2: WhatsApp | O2: Technical | P2: System down | Q2: need help | R2: Need Help | S2: 26/02/2025 | T2: DD/MM/YYYY | U2: 45714 | V2: 45 | W2: 45 | X2: 2h | Y2: 2 | AC2: Pending | AD2: High | AE2: 1 | AF2: 1 | AG2: Lina | AH2: Duplicate | AI2: 1 | AJ2: Bad | AK2: Yes | AL2: bad experience | AN2: ~30 | AO2: 30 | AP2: Yes | AQ2: OK | AR2: Resolution Time Exists Before Closure | AS2: Duplicate Ticket Still Active | AT2: OK | AU2: OK | AX2: 0–17 | AY2: 30–45 min | BA2: $10–30
A3: 1001 | B3: TCK-1001 | D3: V-6925 | E3: 9 | F3: 9 | G3: Female | H3: Iraq | I3: Basra | J3: Mobile Unit | K3: Al Noor Hosp. | L3: Al Noor Hospital | M3: Pharmacy | N3: Phone | O3: Admin | P3: Prescription issue | Q3: waiting too long | R3: Long Wait Time | S3: 04-27-25 | T3: MM-DD-YY | U3: 45774 | V3: 45 | W3: 45 | X3: 5 hours | Y3: 5 | Z3: 05/04/2025 | AA3: DD/MM/YYYY | AB3: 45752 | AC3: Resolved | AD3: High | AE3: 0 | AF3: 0 | AG3: Omar | AH3: Referred | AI3: 2 | AJ3: Bad | AK3: No | AL3: good service | AM3: Positive Feedback | AN3: ~30 | AO3: 30 | AP3: No | AQ3: OK | AR3: OK | AS3: OK | AT3: Review | AU3: OK | AV3: Yes | AW3: 5 | AX3: 0–17 | AY3: 30–45 min | AZ3: 5–8 hrs | BA3: $10–30
A4: 1002 | B4: TCK-1002 | D4: V-2084 | E4: ~30 | F4: 30 | G4: Male | H4: Jordan | I4: Irbid | J4: Clinic | K4: HealthPlus | L4: HealthPlus | M4: Lab | N4: Email | O4: Inquiry | P4: Prescription issue | Q4: waiting too long | R4: Long Wait Time | S4: 2025-02-05 | T4: YYYY-MM-DD | U4: 45693 | V4: 45 | W4: 45 | X4: 48 | Y4: 48 | AC4: Pending | AD4: Medium | AE4: 1 | AF4: 1 | AH4: Dropped | AI4: 1 | AJ4: Bad | AK4: Yes | AL4: good service | AM4: Positive Feedback | AN4: 10 | AO4: 10 | AP4: Yes | AQ4: OK | AR4: Resolution Time Exists Before Closure | AS4: Dropped Ticket Still Active | AT4: OK | AU4: OK | AX4: 18–35 | AY4: 30–45 min | BA4: $10–30
A5: 1003 | B5: TCK-1003 | E5: 71 | F5: 71 | G5: Male | H5: Jordan | I5: Irbid | J5: Mobile Unit | K5: Care Clinic | L5: Care Clinic | M5: ER | N5: Walk-in | O5: Admin | P5: Long wait time | Q5: الخدمة سيئة | R5: Poor Service | S5: 2025-04-27 | T5: YYYY-MM-DD | U5: 45774 | V5: 45 | W5: 45 | X5: 48 | Y5: 48 | Z5: 02-15-25 | AA5: MM-DD-YY | AB5: 45703 | AC5: Pending | AD5: High | AE5: Level 1 | AF5: 1 | AG5: Lina | AH5: Referred | AI5: 3 | AJ5: Neutral | AK5: No | AL5: تأخير في الخدمة | AM5: Service Delay | AN5: 100 USD | AO5: 100 | AP5: Yes | AQ5: Status Mismatch | AR5: Resolution Time Exists Before Closure | AS5: OK | AT5: OK | AU5: OK | AV5: Yes | AX5: 66+ | AY5: 30–45 min | BA5: $61–100
A6: TCK-1004 | B6: TCK-1004 | C6: P-159 | D6: V-2290 | E6: 63 | F6: 63 | G6: Female | H6: Iraq | I6: Basra | J6: Clinic | K6: Alnoor Hospital | L6: Al Noor Hospital | M6: Lab | N6: Web | O6: Inquiry | P6: Prescription issue | Q6: waiting too long | R6: Long Wait Time | S6: 05-16-25 | T6: MM-DD-YY | U6: 45793 | V6: 2 hours | W6: 120 | X6: 5 hours | Y6: 5 | Z6: 05-19-25 | AA6: MM-DD-YY | AB6: 45796 | AC6: Resolved | AD6: High | AE6: 3 | AF6: 3 | AG6: Maya | AH6: Dropped | AI6: 5 | AJ6: Good | AK6: No | AN6: 10 | AO6: 10 | AP6: Yes | AQ6: OK | AR6: OK | AS6: OK | AT6: OK | AU6: OK | AV6: No | AW6: 5 | AX6: 51–65 | AY6: 91–120 min | AZ6: 5–8 hrs | BA6: $10–30
A7: TCK-1005 | B7: TCK-1005 | C7: P-172 | D7: V-4750 | E7: unknown | G7: Male | H7: Jordan | I7: Amman | J7: Clinic | K7: Care Clinic | L7: Care Clinic | M7: Lab | N7: WhatsApp | O7: Technical | P7: Long wait time | Q7: waiting too long | R7: Long Wait Time | S7: 05-27-25 | T7: MM-DD-YY | U7: 45804 | V7: 2 hours | W7: 120 | X7: 5 hours | Y7: 5 | Z7: 02/05/2025 | AA7: DD/MM/YYYY | AB7: 45779 | AC7: Open | AD7: Low | AE7: 3 | AF7: 3 | AG7: Maya | AH7: Dropped | AI7: 4 | AJ7: Good | AK7: No | AL7: bad experience | AN7: 10 | AO7: 10 | AP7: Yes | AQ7: Status Mismatch | AR7: Resolution Time Exists Before Closure | AS7: Dropped Ticket Still Active | AT7: Review | AU7: OK | AV7: Yes | AY7: 91–120 min | BA7: $10–30
A8: TCK-1006 | B8: TCK-1006 | E8: unknown | G8: Female | H8: Lebanon | I8: Saida | J8: Clinic | K8: Al Noor Hosp. | L8: Al Noor Hospital | M8: Lab | N8: Web | O8: Complaint | P8: Billing error | Q8: waiting too long | R8: Long Wait Time | S8: 06-16-25 | T8: MM-DD-YY | U8: 45824 | V8: 30 min | W8: 30 | X8: 2h | Y8: 2 | AC8: Escalated | AD8: Critical | AE8: 1 | AF8: 1 | AG8: John | AH8: Solved | AI8: 2 | AJ8: Bad | AK8: No | AL8: bad experience | AN8: 10 | AO8: 10 | AP8: No | AQ8: OK | AR8: Resolution Time Exists Before Closure | AS8: Solved Ticket Still Active | AT8: OK | AU8: OK | AY8: 30–45 min | BA8: $10–30
A9: TCK-1007 | B9: TCK-1007 | C9: P-403 | D9: V-1958 | E9: 41 | F9: 41 | G9: Male | H9: Iraq | I9: Basra | J9: Pharmacy | K9: Alnoor Hospital | L9: Al Noor Hospital | M9: ER | N9: Web | O9: Complaint | P9: Long wait time | S9: 01-18-25 | T9: MM-DD-YY | U9: 45675 | V9: 30 min | W9: 30 | X9: 5 hours | Y9: 5 | Z9: 2025-04-14 | AA9: YYYY-MM-DD | AB9: 45761 | AC9: Resolved | AD9: Low | AE9: Level 1 | AF9: 1 | AG9: Sara | AH9: Dropped | AI9: good | AJ9: Good | AL9: bad experience | AN9: 100 USD | AO9: 100 | AP9: No | AQ9: OK | AR9: OK | AS9: OK | AT9: OK | AU9: OK | AV9: No | AW9: 5 | AX9: 36–50 | AY9: 30–45 min | AZ9: 5–8 hrs | BA9: $61–100
A10: TCK-1008 | B10: TCK-1008 | E10: 10 | F10: 10 | G10: Female | H10: Iraq | I10: Baghdad | J10: Hospital | K10: Al Noor Hosp. | L10: Al Noor Hospital | M10: Reception | N10: WhatsApp | O10: Technical | P10: Prescription issue | Q10: need help | R10: Need Help | S10: 03/02/2025 | T10: DD/MM/YYYY | U10: 45691 | V10: 30 min | W10: 30 | X10: 5 hours | Y10: 5 | Z10: 05/04/2025 | AA10: DD/MM/YYYY | AB10: 45752 | AC10: Escalated | AD10: High | AE10: Level 1 | AF10: 1 | AH10: Solved | AI10: good | AJ10: Good | AL10: مشكلة في الفاتورة | AM10: Billing Issue | AN10: 50 | AO10: 50 | AP10: Yes | AQ10: Status Mismatch | AR10: Resolution Time Exists Before Closure | AS10: Solved Ticket Still Active | AT10: OK | AU10: Review | AV10: No | AX10: 0–17 | AY10: 30–45 min | BA10: $31–60
A11: 1009 | B11: TCK-1009 | C11: P-719 | D11: V-6617 | E11: ~30 | F11: 30 | G11: Male | H11: Jordan | I11: Zarqa | J11: Pharmacy | K11: Care Clinic | L11: Care Clinic | M11: ER | N11: Phone | O11: Admin | P11: Prescription issue | Q11: waiting too long | R11: Long Wait Time | S11: 2025-01-12 | T11: YYYY-MM-DD | U11: 45669 | V11: 45 | W11: 45 | X11: 5 hours | Y11: 5 | Z11: 13/06/2025 | AA11: DD/MM/YYYY | AB11: 45821 | AC11: Resolved | AD11: Critical | AE11: Level 1 | AF11: 1 | AG11: John | AH11: Solved | AI11: 1 | AJ11: Bad | AK11: Yes | AN11: 20 | AO11: 20 | AP11: Yes | AQ11: OK | AR11: OK | AS11: OK | AT11: OK | AU11: OK | AV11: No | AW11: 5 | AX11: 18–35 | AY11: 30–45 min | AZ11: 5–8 hrs | BA11: $10–30
A12: 1010 | B12: TCK-1010 | C12: P-473 | D12: V-6862 | E12: 88 | F12: 88 | G12: Male | H12: Iraq | I12: Mosul | J12: Mobile Unit | K12: HealthPlus | L12: HealthPlus | M12: Reception | N12: WhatsApp | O12: Inquiry | P12: Long wait time | S12: 15/02/2025 | T12: DD/MM/YYYY | U12: 45703 | V12: 30 min | W12: 30 | X12: 5 hours | Y12: 5 | Z12: 27/03/2025 | AA12: DD/MM/YYYY | AB12: 45743 | AC12: Pending | AD12: Medium | AE12: 0 | AF12: 0 | AG12: John | AH12: Solved | AI12: bad | AJ12: Good | AK12: No | AL12: good service | AM12: Positive Feedback | AN12: 20 | AO12: 20 | AP12: Yes | AQ12: Status Mismatch | AR12: Resolution Time Exists Before Closure | AS12: Solved Ticket Still Active | AT12: OK | AU12: OK | AV12: No | AX12: 66+ | AY12: 30–45 min | BA12: $10–30
A13: tk_1011 | B13: TCK-1011 | E13: unknown | G13: Male | H13: Egypt | I13: Giza | J13: Pharmacy | K13: Care Clinic | L13: Care Clinic | M13: ER | N13: Phone | O13: Medical | P13: Long wait time | Q13: need help | R13: Need Help | S13: 29/05/2025 | T13: DD/MM/YYYY | U13: 45806 | V13: 30 min | W13: 30 | X13: 2h | Y13: 2 | AC13: Resolved | AD13: High | AE13: 3 | AF13: 3 | AH13: Solved | AI13: 4 | AJ13: Good | AL13: good service | AM13: Positive Feedback | AN13: 20 | AO13: 20 | AP13: No | AQ13: Missing Resolved Date | AR13: OK | AS13: OK | AT13: OK | AU13: Review | AW13: 2 | AY13: 30–45 min | AZ13: ≤4 hrs | BA13: $10–30
A14: 1012 | B14: TCK-1012 | D14: V-6143 | E14: ~30 | F14: 30 | G14: Male | H14: Lebanon | I14: Saida | J14: Pharmacy | K14: Care Clinic | L14: Care Clinic | M14: Lab | N14: Walk-in | O14: Technical | P14: Long wait time | Q14: تأخير في الخدمة | R14: Service Delay | S14: 19/02/2025 | T14: DD/MM/YYYY | U14: 45707 | V14: 2 hours | W14: 120 | X14: 5 hours | Y14: 5 | AC14: Escalated | AD14: Low | AE14: 2 | AF14: 2 | AG14: Hassan | AH14: Referred | AI14: 4 | AJ14: Good | AN14: 100 USD | AO14: 100 | AP14: No | AQ14: OK | AR14: Resolution Time Exists Before Closure | AS14: OK | AT14: OK | AU14: OK | AX14: 18–35 | AY14: 91–120 min | BA14: $61–100
A15: tk_1013 | B15: TCK-1013 | E15: 12 | F15: 12 | G15: Male | H15: Egypt | I15: Giza | J15: Clinic | K15: Alnoor Hospital | L15: Al Noor Hospital | M15: Pharmacy | N15: Phone | O15: Complaint | P15: Long wait time | Q15: need help | R15: Need Help | S15: 05-02-25 | T15: MM-DD-YY | U15: 45779 | V15: 30 min | W15: 30 | X15: -1 | Z15: 04-17-25 | AA15: MM-DD-YY | AB15: 45764 | AC15: Resolved | AD15: Critical | AE15: 3 | AF15: 3 | AG15: John | AH15: Referred | AI15: 2 | AJ15: Bad | AK15: Yes | AL15: bad experience | AN15: 10 | AO15: 10 | AP15: No | AQ15: OK | AR15: Missing Resolution Time | AS15: OK | AT15: OK | AU15: OK | AV15: Yes | AX15: 0–17 | AY15: 30–45 min | BA15: $10–30
A16: 1014 | B16: TCK-1014 | E16: ~30 | F16: 30 | G16: Female | H16: Jordan | I16: Amman | J16: Pharmacy | K16: HealthPlus | L16: HealthPlus | M16: Pharmacy | N16: Email | O16: Admin | P16: Prescription issue | Q16: waiting too long | R16: Long Wait Time | S16: 03-05-25 | T16: MM-DD-YY | U16: 45721 | V16: 45 | W16: 45 | X16: 48 | Y16: 48 | Z16: 05-05-25 | AA16: MM-DD-YY | AB16: 45782 | AC16: Pending | AD16: Critical | AE16: 0 | AF16: 0 | AG16: Hassan | AH16: Referred | AI16: 3 | AJ16: Neutral | AK16: Yes | AL16: good service | AM16: Positive Feedback | AN16: 50 | AO16: 50 | AP16: Yes | AQ16: Status Mismatch | AR16: Resolution Time Exists Before Closure | AS16: OK | AT16: Review | AU16: OK | AV16: No | AX16: 18–35 | AY16: 30–45 min | BA16: $31–60
A17: TCK-1015 | B17: TCK-1015 | E17: 54 | F17: 54 | G17: Female | H17: Jordan | I17: Amman | J17: Pharmacy | K17: HealthPlus | L17: HealthPlus | M17: Reception | N17: Phone | O17: Technical | P17: System down | S17: 2025-05-03 | T17: YYYY-MM-DD | U17: 45780 | V17: 45 | W17: 45 | X17: 1 day | Y17: 24 | Z17: 10/04/2025 | AA17: DD/MM/YYYY | AB17: 45757 | AC17: Escalated | AD17: Medium | AE17: 2 | AF17: 2 | AG17: John | AH17: Dropped | AI17: 1 | AJ17: Bad | AK17: No | AL17: bad experience | AN17: 50 | AO17: 50 | AP17: No | AQ17: Status Mismatch | AR17: Resolution Time Exists Before Closure | AS17: Dropped Ticket Still Active | AT17: OK | AU17: OK | AV17: Yes | AX17: 51–65 | AY17: 30–45 min | BA17: $31–60
A18: tk_1016 | B18: TCK-1016 | C18: P-677 | E18: unknown | G18: Female | H18: Jordan | I18: Zarqa | J18: Hospital | K18: Care Clinic | L18: Care Clinic | M18: Lab | N18: Walk-in | O18: Inquiry | P18: System down | Q18: الدكتور لم يحضر | R18: Doctor Did Not Attend | S18: 25/03/2025 | T18: DD/MM/YYYY | U18: 45741 | V18: 2 hours | W18: 120 | X18: 1 day | Y18: 24 | Z18: 18/04/2025 | AA18: DD/MM/YYYY | AB18: 45765 | AC18: Escalated | AD18: Low | AE18: Level 1 | AF18: 1 | AG18: Ali | AH18: Duplicate | AI18: 2 | AJ18: Bad | AK18: Yes | AL18: تأخير في الخدمة | AM18: Service Delay | AN18: 10 | AO18: 10 | AP18: Yes | AQ18: Status Mismatch | AR18: Resolution Time Exists Before Closure | AS18: Duplicate Ticket Still Active | AT18: OK | AU18: OK | AV18: No | AY18: 91–120 min | BA18: $10–30
A19: TCK-1017 | B19: TCK-1017 | C19: P-584 | E19: unknown | G19: Male | H19: Jordan | I19: Amman | J19: Clinic | K19: Al Noor Hosp. | L19: Al Noor Hospital | M19: Pharmacy | N19: Walk-in | O19: Complaint | P19: Wrong appointment | Q19: تأخير في الخدمة | R19: Service Delay | S19: 07/01/2025 | T19: DD/MM/YYYY | U19: 45664 | V19: 2 hours | W19: 120 | X19: -1 | Z19: 2025-02-20 | AA19: YYYY-MM-DD | AB19: 45708 | AC19: Open | AD19: High | AE19: Level 1 | AF19: 1 | AG19: Sara | AH19: Solved | AI19: 3 | AJ19: Neutral | AL19: bad experience | AN19: ~30 | AO19: 30 | AP19: No | AQ19: Status Mismatch | AR19: OK | AS19: Solved Ticket Still Active | AT19: OK | AU19: OK | AV19: No | AY19: 91–120 min | BA19: $10–30
A20: 1018 | B20: TCK-1018 | E20: ~30 | F20: 30 | G20: Female | H20: Lebanon | I20: Tripoli | J20: Mobile Unit | K20: HealthPlus | L20: HealthPlus | M20: Lab | N20: Email | O20: Technical | P20: Prescription issue | S20: 2025-03-24 | T20: YYYY-MM-DD | U20: 45740 | V20: 30 min | W20: 30 | X20: 1 day | Y20: 24 | AC20: Resolved | AD20: Critical | AE20: 2 | AF20: 2 | AG20: Ali | AH20: Dropped | AI20: bad | AJ20: Good | AK20: Yes | AL20: good service | AM20: Positive Feedback | AN20: 20 | AO20: 20 | AP20: No | AQ20: Missing Resolved Date | AR20: OK | AS20: OK | AT20: OK | AU20: OK | AW20: 24 | AX20: 18–35 | AY20: 30–45 min | AZ20: 9–24 hrs | BA20: $10–30
A21: tk_1019 | B21: TCK-1019 | C21: P-110 | D21: V-2402 | E21: unknown | G21: Female | H21: Jordan | I21: Zarqa | J21: Clinic | K21: HealthPlus | L21: HealthPlus | M21: Lab | N21: Email | O21: Complaint | P21: Billing error | Q21: billing not clear | R21: Billing Issue | S21: 2025-03-17 | T21: YYYY-MM-DD | U21: 45733 | V21: 2 hours | W21: 120 | X21: 5 hours | Y21: 5 | AC21: Escalated | AD21: High | AE21: 3 | AF21: 3 | AH21: Duplicate | AI21: 3 | AJ21: Neutral | AK21: No | AN21: 50 | AO21: 50 | AP21: No | AQ21: OK | AR21: Resolution Time Exists Before Closure | AS21: Duplicate Ticket Still Active | AT21: OK | AU21: Review | AY21: 91–120 min | BA21: $31–60
A22: tk_1020 | B22: TCK-1020 | C22: P-648 | D22: V-4138 | E22: unknown | G22: Female | H22: Iraq | I22: Baghdad | J22: Mobile Unit | K22: Al Noor Hosp. | L22: Al Noor Hospital | M22: Pharmacy | N22: Walk-in | O22: Inquiry | P22: Prescription issue | Q22: need help | R22: Need Help | S22: 15/02/2025 | T22: DD/MM/YYYY | U22: 45703 | V22: 30 min | W22: 30 | X22: 48 | Y22: 48 | Z22: 02/02/2025 | AA22: DD/MM/YYYY | AB22: 45690 | AC22: Open | AD22: High | AE22: 1 | AF22: 1 | AG22: Fatima | AH22: Solved | AI22: bad | AJ22: Good | AK22: Yes | AL22: good service | AM22: Positive Feedback | AN22: 100 USD | AO22: 100 | AP22: No | AQ22: Status Mismatch | AR22: Resolution Time Exists Before Closure | AS22: Solved Ticket Still Active | AT22: OK | AU22: OK | AV22: Yes | AY22: 30–45 min | BA22: $61–100
A23: 1021 | B23: TCK-1021 | D23: V-2869 | E23: unknown | G23: Male | H23: Egypt | I23: Giza | J23: Hospital | K23: Alnoor Hospital | L23: Al Noor Hospital | M23: Pharmacy | N23: Web | O23: Medical | P23: Billing error | Q23: billing not clear | R23: Billing Issue | S23: 2025-03-05 | T23: YYYY-MM-DD | U23: 45721 | V23: 2 hours | W23: 120 | X23: 48 | Y23: 48 | Z23: 06-02-25 | AA23: MM-DD-YY | AB23: 45810 | AC23: Pending | AD23: Critical | AE23: 3 | AF23: 3 | AG23: Fatima | AH23: Duplicate | AI23: bad | AJ23: Good | AL23: good service | AM23: Positive Feedback | AN23: ~30 | AO23: 30 | AP23: No | AQ23: Status Mismatch | AR23: Resolution Time Exists Before Closure | AS23: Duplicate Ticket Still Active | AT23: OK | AU23: OK | AV23: No | AY23: 91–120 min | BA23: $10–30
A24: TCK-1022 | B24: TCK-1022 | C24: P-345 | D24: V-2229 | E24: unknown | G24: Female | H24: Lebanon | I24: Beirut | J24: Pharmacy | K24: Care Clinic | L24: Care Clinic | M24: ER | N24: WhatsApp | O24: Medical | P24: Missing record | Q24: need help | R24: Need Help | S24: 03-14-25 | T24: MM-DD-YY | U24: 45730 | V24: 2 hours | W24: 120 | X24: 2h | Y24: 2 | AC24: Pending | AD24: Medium | AE24: 3 | AF24: 3 | AG24: Sara | AH24: Referred | AI24: good | AJ24: Good | AK24: No | AL24: good service | AM24: Positive Feedback | AN24: 50 | AO24: 50 | AP24: Yes | AQ24: OK | AR24: Resolution Time Exists Before Closure | AS24: OK | AT24: OK | AU24: OK | AY24: 91–120 min | BA24: $31–60
A25: TCK-1023 | B25: TCK-1023 | E25: ~30 | F25: 30 | G25: Female | H25: Lebanon | I25: Beirut | J25: Pharmacy | K25: Al Noor Hosp. | L25: Al Noor Hospital | M25: Reception | N25: Phone | O25: Admin | P25: Missing record | Q25: billing not clear | R25: Billing Issue | S25: 03-24-25 | T25: MM-DD-YY | U25: 45740 | V25: 45 | W25: 45 | X25: 2h | Y25: 2 | Z25: 2025-01-24 | AA25: YYYY-MM-DD | AB25: 45681 | AC25: Pending | AD25: High | AE25: Level 1 | AF25: 1 | AG25: Ali | AH25: Referred | AI25: 4 | AJ25: Good | AL25: مشكلة في الفاتورة | AM25: Billing Issue | AN25: ~30 | AO25: 30 | AP25: No | AQ25: Status Mismatch | AR25: Resolution Time Exists Before Closure | AS25: OK | AT25: OK | AU25: OK | AV25: Yes | AX25: 18–35 | AY25: 30–45 min | BA25: $10–30
A26: 1024 | B26: TCK-1024 | D26: V-6260 | E26: unknown | G26: Female | H26: Jordan | I26: Irbid | J26: Pharmacy | K26: Care Clinic | L26: Care Clinic | M26: Lab | N26: Web | O26: Complaint | P26: System down | S26: 23/01/2025 | T26: DD/MM/YYYY | U26: 45680 | V26: 45 | W26: 45 | X26: 1 day | Y26: 24 | Z26: 30/01/2025 | AA26: DD/MM/YYYY | AB26: 45687 | AC26: Resolved | AD26: Critical | AE26: 3 | AF26: 3 | AG26: Ali | AH26: Referred | AI26: 5 | AJ26: Good | AK26: Yes | AL26: تأخير في الخدمة | AM26: Service Delay | AN26: 100 USD | AO26: 100 | AP26: No | AQ26: OK | AR26: OK | AS26: OK | AT26: OK | AU26: OK | AV26: No | AW26: 24 | AY26: 30–45 min | AZ26: 9–24 hrs | BA26: $61–100
A27: 1025 | B27: TCK-1025 | D27: V-2989 | E27: ~30 | F27: 30 | G27: Female | H27: Egypt | I27: Cairo | J27: Clinic | K27: Care Clinic | L27: Care Clinic | M27: Reception | N27: Phone | O27: Technical | P27: System down | Q27: billing not clear | R27: Billing Issue | S27: 2025-01-24 | T27: YYYY-MM-DD | U27: 45681 | V27: 30 min | W27: 30 | X27: -1 | Z27: 01-31-25 | AA27: MM-DD-YY | AB27: 45688 | AC27: Escalated | AD27: High | AE27: Level 1 | AF27: 1 | AG27: Hassan | AH27: Dropped | AI27: bad | AJ27: Good | AK27: No | AN27: ~30 | AO27: 30 | AP27: Yes | AQ27: Status Mismatch | AR27: OK | AS27: Dropped Ticket Still Active | AT27: OK | AU27: OK | AV27: No | AX27: 18–35 | AY27: 30–45 min | BA27: $10–30
A28: TCK-1026 | B28: TCK-1026 | E28: unknown | G28: Male | H28: Egypt | I28: Alexandria | J28: Pharmacy | K28: Alnoor Hospital | L28: Al Noor Hospital | M28: Lab | N28: Web | O28: Admin | P28: Prescription issue | S28: 03-27-25 | T28: MM-DD-YY | U28: 45743 | V28: 2 hours | W28: 120 | X28: -1 | Z28: 2025-03-24 | AA28: YYYY-MM-DD | AB28: 45740 | AC28: Resolved | AD28: Critical | AE28: 1 | AF28: 1 | AG28: John | AH28: Solved | AI28: 3 | AJ28: Neutral | AK28: No | AL28: bad experience | AN28: ~30 | AO28: 30 | AP28: No | AQ28: OK | AR28: Missing Resolution Time | AS28: OK | AT28: OK | AU28: OK | AV28: Yes | AY28: 91–120 min | BA28: $10–30
A29: 1027 | B29: TCK-1027 | D29: V-1251 | E29: ~30 | F29: 30 | G29: Female | H29: Jordan | I29: Zarqa | J29: Hospital | K29: HealthPlus | L29: HealthPlus | M29: Billing | N29: Walk-in | O29: Technical | P29: Missing record | Q29: need help | R29: Need Help | S29: 04-12-25 | T29: MM-DD-YY | U29: 45759 | V29: 30 min | W29: 30 | X29: 1 day | Y29: 24 | AC29: Pending | AD29: Critical | AE29: Level 1 | AF29: 1 | AG29: Ali | AH29: Solved | AI29: 2 | AJ29: Bad | AK29: Yes | AL29: good service | AM29: Positive Feedback | AN29: 20 | AO29: 20 | AP29: Yes | AQ29: OK | AR29: Resolution Time Exists Before Closure | AS29: Solved Ticket Still Active | AT29: OK | AU29: OK | AX29: 18–35 | AY29: 30–45 min | BA29: $10–30
A30: TCK-1028 | B30: TCK-1028 | E30: unknown | G30: Female | H30: Egypt | I30: Cairo | J30: Clinic | K30: Alnoor Hospital | L30: Al Noor Hospital | M30: Reception | N30: Email | O30: Technical | P30: Missing record | S30: 2025-02-16 | T30: YYYY-MM-DD | U30: 45704 | V30: 1h | W30: 60 | X30: 2h | Y30: 2 | Z30: 06/06/2025 | AA30: DD/MM/YYYY | AB30: 45814 | AC30: Escalated | AD30: Medium | AE30: 1 | AF30: 1 | AG30: Fatima | AH30: Duplicate | AI30: 4 | AJ30: Good | AK30: Yes | AN30: 10 | AO30: 10 | AP30: No | AQ30: Status Mismatch | AR30: Resolution Time Exists Before Closure | AS30: Duplicate Ticket Still Active | AT30: OK | AU30: OK | AV30: No | AY30: 46–60 min | BA30: $10–30
A31: tk_1029 | B31: TCK-1029 | E31: 39 | F31: 39 | G31: Female | H31: Iraq | I31: Mosul | J31: Pharmacy | K31: Al Noor Hosp. | L31: Al Noor Hospital | M31: Pharmacy | N31: Email | O31: Technical | P31: Prescription issue | Q31: waiting too long | R31: Long Wait Time | S31: 28/05/2025 | T31: DD/MM/YYYY | U31: 45805 | V31: 45 | W31: 45 | X31: 2h | Y31: 2 | AC31: Open | AD31: Low | AE31: Level 1 | AF31: 1 | AG31: Fatima | AH31: Duplicate | AI31: bad | AJ31: Good | AK31: No | AN31: 100 USD | AO31: 100 | AP31: No | AQ31: OK | AR31: Resolution Time Exists Before Closure | AS31: Duplicate Ticket Still Active | AT31: OK | AU31: OK | AX31: 36–50 | AY31: 30–45 min | BA31: $61–100
A32: tk_1030 | B32: TCK-1030 | C32: P-199 | E32: ~30 | F32: 30 | G32: Male | H32: Jordan | I32: Irbid | J32: Clinic | K32: Al Noor Hosp. | L32: Al Noor Hospital | M32: Billing | N32: Walk-in | O32: Admin | P32: Long wait time | Q32: الدكتور لم يحضر | R32: Doctor Did Not Attend | S32: 2025-02-21 | T32: YYYY-MM-DD | U32: 45709 | V32: 45 | W32: 45 | X32: 48 | Y32: 48 | Z32: 09/05/2025 | AA32: DD/MM/YYYY | AB32: 45786 | AC32: Pending | AD32: Critical | AE32: 2 | AF32: 2 | AG32: Maya | AH32: Solved | AI32: 4 | AJ32: Good | AK32: Yes | AL32: bad experience | AN32: 20 | AO32: 20 | AP32: Yes | AQ32: Status Mismatch | AR32: Resolution Time Exists Before Closure | AS32: Solved Ticket Still Active | AT32: OK | AU32: OK | AV32: No | AX32: 18–35 | AY32: 30–45 min | BA32: $10–30
A33: 1031 | B33: TCK-1031 | C33: P-649 | E33: ~30 | F33: 30 | G33: Male | H33: Egypt | I33: Alexandria | J33: Pharmacy | K33: Care Clinic | L33: Care Clinic | M33: ER | N33: WhatsApp | O33: Admin | P33: Billing error | Q33: waiting too long | R33: Long Wait Time | S33: 06-08-25 | T33: MM-DD-YY | U33: 45816 | V33: 45 | W33: 45 | X33: 48 | Y33: 48 | Z33: 02-26-25 | AA33: MM-DD-YY | AB33: 45714 | AC33: Resolved | AD33: Critical | AE33: 2 | AF33: 2 | AG33: John | AH33: Solved | AI33: 2 | AJ33: Bad | AK33: Yes | AL33: good service | AM33: Positive Feedback | AN33: 10 | AO33: 10 | AP33: No | AQ33: OK | AR33: OK | AS33: OK | AT33: OK | AU33: OK | AV33: Yes | AW33: 48 | AX33: 18–35 | AY33: 30–45 min | AZ33: 25–48 hrs | BA33: $10–30
A34: 1032 | B34: TCK-1032 | E34: 84 | F34: 84 | G34: Female | H34: Egypt | I34: Cairo | J34: Pharmacy | K34: Care Clinic | L34: Care Clinic | M34: ER | N34: Walk-in | O34: Inquiry | P34: System down | Q34: need help | R34: Need Help | S34: 2025-04-24 | T34: YYYY-MM-DD | U34: 45771 | V34: 45 | W34: 45 | X34: 2h | Y34: 2 | AC34: Open | AD34: Critical | AE34: 2 | AF34: 2 | AG34: Lina | AH34: Solved | AI34: bad | AJ34: Good | AK34: No | AL34: الدكتور لم يحضر | AM34: Doctor Unavailable | AN34: 10 | AO34: 10 | AP34: Yes | AQ34: OK | AR34: Resolution Time Exists Before Closure | AS34: Solved Ticket Still Active | AT34: OK | AU34: OK | AX34: 66+ | AY34: 30–45 min | BA34: $10–30
A35: TCK-1033 | B35: TCK-1033 | C35: P-949 | D35: V-4538 | E35: 43 | F35: 43 | G35: Female | H35: Lebanon | I35: Beirut | J35: Hospital | K35: Care Clinic | L35: Care Clinic | M35: Pharmacy | N35: WhatsApp | O35: Technical | P35: Prescription issue | Q35: need help | R35: Need Help | S35: 2025-02-14 | T35: YYYY-MM-DD | U35: 45702 | V35: 30 min | W35: 30 | X35: 5 hours | Y35: 5 | Z35: 04/01/2025 | AA35: DD/MM/YYYY | AB35: 45661 | AC35: Resolved | AD35: High | AE35: 0 | AF35: 0 | AG35: Omar | AH35: Duplicate | AI35: 1 | AJ35: Bad | AK35: No | AL35: bad experience | AN35: ~30 | AO35: 30 | AP35: Yes | AQ35: OK | AR35: OK | AS35: OK | AT35: Review | AU35: OK | AV35: Yes | AW35: 5 | AX35: 36–50 | AY35: 30–45 min | AZ35: 5–8 hrs | BA35: $10–30
A36: tk_1034 | B36: TCK-1034 | C36: P-326 | E36: ~30 | F36: 30 | G36: Male | H36: Lebanon | I36: Saida | J36: Hospital | K36: HealthPlus | L36: HealthPlus | M36: Lab | N36: Email | O36: Complaint | P36: System down | Q36: billing not clear | R36: Billing Issue | S36: 2025-04-24 | T36: YYYY-MM-DD | U36: 45771 | V36: 30 min | W36: 30 | X36: 1 day | Y36: 24 | Z36: 2025-06-05 | AA36: YYYY-MM-DD | AB36: 45813 | AC36: Closed | AD36: High | AE36: Level 1 | AF36: 1 | AH36: Duplicate | AI36: 4 | AJ36: Good | AL36: تأخير في الخدمة | AM36: Service Delay | AN36: 100 USD | AO36: 100 | AP36: No | AQ36: OK | AR36: OK | AS36: OK | AT36: OK | AU36: Review | AV36: No | AW36: 24 | AX36: 18–35 | AY36: 30–45 min | AZ36: 9–24 hrs | BA36: $61–100
A37: 1035 | B37: TCK-1035 | C37: P-562 | E37: unknown | G37: Female | H37: Egypt | I37: Alexandria | J37: Hospital | K37: Care Clinic | L37: Care Clinic | M37: Lab | N37: Walk-in | O37: Medical | P37: Prescription issue | Q37: waiting too long | R37: Long Wait Time | S37: 02-09-25 | T37: MM-DD-YY | U37: 45697 | V37: 2 hours | W37: 120 | X37: 2h | Y37: 2 | Z37: 2025-01-24 | AA37: YYYY-MM-DD | AB37: 45681 | AC37: Escalated | AD37: Low | AE37: 2 | AF37: 2 | AG37: Omar | AH37: Solved | AI37: 5 | AJ37: Good | AL37: bad experience | AN37: 100 USD | AO37: 100 | AP37: No | AQ37: Status Mismatch | AR37: Resolution Time Exists Before Closure | AS37: Solved Ticket Still Active | AT37: OK | AU37: OK | AV37: Yes | AY37: 91–120 min | BA37: $61–100
A38: tk_1036 | B38: TCK-1036 | D38: V-2697 | E38: ~30 | F38: 30 | G38: Female | H38: Lebanon | I38: Saida | J38: Clinic | K38: Al Noor Hosp. | L38: Al Noor Hospital | M38: Billing | N38: Web | O38: Medical | P38: Billing error | S38: 03-13-25 | T38: MM-DD-YY | U38: 45729 | V38: 1h | W38: 60 | X38: -1 | Z38: 05-24-25 | AA38: MM-DD-YY | AB38: 45801 | AC38: Resolved | AD38: High | AE38: 0 | AF38: 0 | AG38: Omar | AH38: Duplicate | AI38: good | AJ38: Good | AK38: Yes | AN38: 50 | AO38: 50 | AP38: No | AQ38: OK | AR38: Missing Resolution Time | AS38: OK | AT38: Review | AU38: OK | AV38: No | AX38: 18–35 | AY38: 46–60 min | BA38: $31–60
A39: TCK-1037 | B39: TCK-1037 | C39: P-858 | D39: V-2503 | E39: unknown | G39: Female | H39: Lebanon | I39: Bekaa | J39: Mobile Unit | K39: Alnoor Hospital | L39: Al Noor Hospital | M39: Billing | N39: Walk-in | O39: Medical | P39: Wrong appointment | Q39: الدكتور لم يحضر | R39: Doctor Did Not Attend | S39: 2025-06-02 | T39: YYYY-MM-DD | U39: 45810 | V39: 30 min | W39: 30 | X39: 5 hours | Y39: 5 | Z39: 02-10-25 | AA39: MM-DD-YY | AB39: 45698 | AC39: Resolved | AD39: Low | AE39: 2 | AF39: 2 | AG39: Fatima | AH39: Dropped | AI39: 4 | AJ39: Good | AL39: good service | AM39: Positive Feedback | AN39: ~30 | AO39: 30 | AP39: No | AQ39: OK | AR39: OK | AS39: OK | AT39: OK | AU39: OK | AV39: Yes | AW39: 5 | AY39: 30–45 min | AZ39: 5–8 hrs | BA39: $10–30
A40: 1038 | B40: TCK-1038 | E40: 6 | F40: 6 | G40: Female | H40: Iraq | I40: Baghdad | J40: Hospital | K40: Al Noor Hosp. | L40: Al Noor Hospital | M40: Pharmacy | N40: Walk-in | O40: Inquiry | P40: Long wait time | Q40: billing not clear | R40: Billing Issue | S40: 07/03/2025 | T40: DD/MM/YYYY | U40: 45723 | V40: 45 | W40: 45 | X40: 2h | Y40: 2 | AC40: Closed | AD40: Medium | AE40: 3 | AF40: 3 | AH40: Referred | AI40: 5 | AJ40: Good | AL40: good service | AM40: Positive Feedback | AN40: 50 | AO40: 50 | AP40: Yes | AQ40: Missing Resolved Date | AR40: OK | AS40: OK | AT40: OK | AU40: Review | AW40: 2 | AX40: 0–17 | AY40: 30–45 min | AZ40: ≤4 hrs | BA40: $31–60
...

Sheet EDA
B1: First Response Time | C1: Resolution Time | D1: Patient Age | E1: Cost_estimate
A2: Minimum | B2: =MIN('Clean Data'!W:W) -> 30 | C2: =MIN('Clean Data'!AW:AW) -> 2 | D2: =MIN('Clean Data'!F:F) -> 1 | E2: =MIN('Clean Data'!AO:AO) -> 10
A3: Maximum | B3: =MAX('Clean Data'!W:W) -> 120 | C3: =MAX('Clean Data'!AW:AW) -> 48 | D3: =MAX('Clean Data'!F:F) -> 90 | E3: =MAX(('Clean Data'!AO:AO)) -> 100
A4: Average | B4: =AVERAGE('Clean Data'!W:W) -> 64.967143 | C4: =AVERAGE(('Clean Data'!AW:AW)) -> 19.526638 | D4: =AVERAGE('Clean Data'!F:F) -> 38.298641 | E4: =AVERAGE(('Clean Data'!AO:AO)) -> 41.908571
A5: Median | B5: =MEDIAN('Clean Data'!W:W) -> 60 | C5: =MEDIAN('Clean Data'!AW:AW) -> 5 | D5: =MEDIAN('Clean Data'!F:F) -> 30 | E5: =MEDIAN(('Clean Data'!AO:AO)) -> 30
A6: Valid Records | B6: =COUNT('Clean Data'!W:W) -> 3500 | C6: =COUNT('Clean Data'!AW:AW) -> 1145 | D6: =COUNT('Clean Data'!F:F) -> 2354 | E6: =COUNT(('Clean Data'!AO:AO)) -> 3500
A7: Total | E7: =SUM(('Clean Data'!AO:AO)) -> 146680

Sheet Charts
A45: Ticket Issue | B45: Cost Total | C45: Cumulative Cost
A46: ='Cost vs Ticket Description'!A4 -> Billing Issue | B46: ='Cost vs Ticket Description'!B4 -> 35250 | C46: =B46/$B$52*100 -> 30.551222
A47: ='Cost vs Ticket Description'!A5 -> Long Wait Time | B47: ='Cost vs Ticket Description'!B5 -> 29390 | C47: =B47/$B$52*100 -> 25.472352
A48: ='Cost vs Ticket Description'!A6 -> Need Help | B48: ='Cost vs Ticket Description'!B6 -> 28090 | C48: =B48/$B$52*100 -> 24.34564
A49: ='Cost vs Ticket Description'!A7 -> Poor Service | B49: ='Cost vs Ticket Description'!B7 -> 7910 | C49: =B49/$B$52*100 -> 6.8556076
A50: ='Cost vs Ticket Description'!A8 -> Service Delay | B50: ='Cost vs Ticket Description'!B8 -> 7470 | C50: =B50/$B$52*100 -> 6.474259
A51: ='Cost vs Ticket Description'!A9 -> Doctor No Show | B51: ='Cost vs Ticket Description'!B9 -> 7270 | C51: =B51/$B$52*100 -> 6.3009187
A52: ='Cost vs Ticket Description'!A10 -> Grand Total | B52: ='Cost vs Ticket Description'!B10 -> 115380 | C52: =SUM((C46:C51)) -> 100

Sheet Refresh_Log
A1: Refresh Time
A2: 46233.528

Sheet Create_Date Analysis
A3: Row Labels | B3: Count of Ticket_ID_Clean
A4: Jan | B4: 582 | F4: Month | G4: Minimum | H4: Maximum
A5: Feb | B5: 587 | F5: Jan | G5: 10 | H5: 27
A6: Mar | B6: 571 | F6: Feb | G6: 15 | H6: 30
A7: Apr | B7: 589 | F7: March | G7: 11 | H7: 36
A8: May | B8: 588 | F8: April | G8: 10 | H8: 26
A9: Jun | B9: 583 | F9: May | G9: 6 | H9: 29
A10: Grand Total | B10: 3500 | F10: June | G10: 11 | H10: 33

Sheet Country Distribution
A3: Row Labels | B3: Count of Ticket_ID_Clean
A4: Egypt | B4: 900
A5: Iraq | B5: 830
A6: Jordan | B6: 870
A7: Lebanon | B7: 900
A8: Grand Total | B8: 3500

Sheet Facility Distribution
A3: Row Labels | B3: Count of Ticket_ID_Clean
A4: Al Noor Hospital | B4: 1747
A5: Care Clinic | B5: 875
A6: HealthPlus | B6: 878
A7: Grand Total | B7: 3500

Sheet Channel Distribution
A3: Row Labels | B3: Count of Ticket_ID_Clean
A4: Email | B4: 730
A5: Phone | B5: 704
A6: Walk-in | B6: 685
A7: Web | B7: 701
A8: WhatsApp | B8: 680
A9: Grand Total | B9: 3500

Sheet Status Distribution
A3: Row Labels | B3: Count of Ticket_ID_Clean
A4: Closed | B4: 484
A5: Escalated | B5: 506
A6: Open | B6: 524
A7: Pending | B7: 1005
A8: Resolved | B8: 981
A9: Grand Total | B9: 3500

Sheet Priority Distribution
A3: Row Labels | B3: Count of Ticket_ID_Clean
A4: Low | B4: 868
A5: High | B5: 855
A6: Critical | B6: 876
A7: Medium | B7: 901
A8: Grand Total | B8: 3500

Sheet Escalated_Tickets distribution
A3: Row Labels | B3: Count of Ticket_ID_Clean
A4: 0 | B4: 722
A5: 1 | B5: 1367
A6: 2 | B6: 668
A7: 3 | B7: 743
A8: Grand Total | B8: 3500

Sheet Ticket_Description Distribution
A3: Row Labels | B3: Count of Ticket_ID_Clean
A4: Poor Service | B4: 0.061981982
A5: Doctor Did Not Attend | B5: 0.063423423
A6: Service Delay | B6: 0.063423423
A7: Need Help | B7: 0.24684685
A8: Long Wait Time | B8: 0.25621622
A9: Billing Issue | B9: 0.30810811
A10: Grand Total | B10: 1

Sheet Satisfaction categories Distrib
A3: Row Labels | B3: Count of Ticket_ID_Clean
A4: Bad | B4: 0.28742857
A5: Good | B5: 0.57342857
A6: Neutral | B6: 0.13914286
A7: Grand Total | B7: 1

Sheet Tickets Gender Distribution
A3: Row Labels | B3: Count of Ticket_ID_Clean
A4: Female | B4: 2131
A5: Male | B5: 1369
A6: Grand Total | B6: 3500

Sheet First_Response_Groups Distrib.
A3: Row Labels | B3: Count of Ticket_ID_Clean
A4: 30–45 min | B4: 1703
A5: 46–60 min | B5: 870
A6: 91–120 min | B6: 927
A7: (blank)
A8: Grand Total | B8: 3500

Sheet Age Group Distribution
A3: Row Labels | B3: Count of Ticket_ID_Clean
A4: 0–17 | B4: 226
A5: (blank) | B5: 1146
A6: 18–35 | B6: 1378
A7: 66+ | B7: 337
A8: 51–65 | B8: 216
A9: 36–50 | B9: 197
A10: Grand Total | B10: 3500

Sheet Cost Estimate Distribution
A3: Row Labels | B3: Count of Ticket_ID_Clean
A4: $10–30 | B4: 2064
A5: $31–60 | B5: 759
A6: $61–100 | B6: 677
A7: (blank)
A8: Grand Total | B8: 3500

Sheet Resolution Time Groups
A3: Row Labels | B3: Count of Ticket_ID_Clean
A4: ≤4 hrs | B4: 0.25764192
A5: 25–48 hrs | B5: 0.2489083
A6: 5–8 hrs | B6: 0.25152838
A7: 9–24 hrs | B7: 0.2419214
A8: Grand Total | B8: 1

Sheet Country vs Ticket Description
A3: Count of Ticket_ID_Clean | B3: Column Labels
A4: Row Labels | B4: Billing Issue | C4: Long Wait Time | D4: Need Help | E4: Doctor Did Not Attend | F4: Service Delay | G4: Poor Service | H4: Grand Total
A5: Egypt | B5: 0.32621083 | C5: 0.26780627 | D5: 0.23076923 | E5: 0.064102564 | F5: 0.055555556 | G5: 0.055555556 | H5: 1
A6: Iraq | B6: 0.30627871 | C6: 0.26646248 | D6: 0.23277182 | E6: 0.065849923 | F6: 0.06431853 | G6: 0.06431853 | H6: 1
A7: Jordan | B7: 0.27930535 | C7: 0.29522431 | D7: 0.24746744 | E7: 0.054992764 | F7: 0.062228654 | G7: 0.060781476 | H7: 1
A8: Lebanon | B8: 0.31961591 | C8: 0.19890261 | D8: 0.27434842 | E8: 0.068587106 | F8: 0.07133059 | G8: 0.067215364 | H8: 1
A9: Grand Total | B9: 0.30810811 | C9: 0.25621622 | D9: 0.24684685 | E9: 0.063423423 | F9: 0.063423423 | G9: 0.061981982 | H9: 1

Sheet Facility vs Ticket Description
A3: Count of Ticket_ID_Clean | B3: Column Labels
A4: Row Labels | B4: Billing Issue | C4: Long Wait Time | D4: Need Help | E4: Doctor Did Not Attend | F4: Service Delay | G4: Poor Service | H4: Grand Total
A5: Al Noor Hospital | B5: 0.31186686 | C5: 0.26700434 | D5: 0.22503618 | E5: 0.060057887 | F5: 0.068017366 | G5: 0.068017366 | H5: 1
A6: HealthPlus | B6: 0.31465517 | C6: 0.24568966 | D6: 0.26293103 | E6: 0.061781609 | F6: 0.060344828 | G6: 0.054597701 | H6: 1
A7: Care Clinic | B7: 0.29411765 | C7: 0.24533716 | D7: 0.27403156 | E7: 0.071736011 | F7: 0.057388809 | G7: 0.057388809 | H7: 1
A8: Grand Total | B8: 0.30810811 | C8: 0.25621622 | D8: 0.24684685 | E8: 0.063423423 | F8: 0.063423423 | G8: 0.061981982 | H8: 1

Sheet Facility vs Frst Repsonse Time
A3: Count of Ticket_ID_Clean | B3: Column Labels
A4: Row Labels | B4: 30–45 min | C4: 91–120 min | D4: 46–60 min | E4: Grand Total
A5: Al Noor Hospital | B5: 0.48540355 | C5: 0.25529479 | D5: 0.25930166 | E5: 1
A6: Care Clinic | B6: 0.496 | C6: 0.26171429 | D6: 0.24228571 | E6: 1
A7: HealthPlus | B7: 0.47949886 | C7: 0.28701595 | D7: 0.23348519 | E7: 1
A8: Grand Total | B8: 0.48657143 | C8: 0.26485714 | D8: 0.24857143 | E8: 1

Sheet Facility vs Resolution Time 
A3: Count of Ticket_ID_Clean | B3: Column Labels
A4: Row Labels | B4: ≤4 hrs | C4: 5–8 hrs | D4: 25–48 hrs | E4: 9–24 hrs | F4: Grand Total
A5: Al Noor Hospital | B5: 0.25744308 | C5: 0.26444834 | D5: 0.23817863 | E5: 0.23992995 | F5: 1
A6: Care Clinic | B6: 0.24914676 | C6: 0.25938567 | D6: 0.24573379 | E6: 0.24573379 | F6: 1
A7: HealthPlus | B7: 0.26690391 | C7: 0.21708185 | D7: 0.27402135 | E7: 0.24199288 | F7: 1
A8: Grand Total | B8: 0.25764192 | C8: 0.25152838 | D8: 0.2489083 | E8: 0.2419214 | F8: 1

Sheet Facility vs Patient Satisfactio
A3: Count of Ticket_ID_Clean | B3: Column Labels
A4: Row Labels | B4: Good | C4: Bad | D4: Neutral | E4: Grand Total
A5: Al Noor Hospital | B5: 0.57698912 | C5: 0.28792215 | D5: 0.13508872 | E5: 1
A6: Care Clinic | B6: 0.58171429 | C6: 0.27428571 | D6: 0.144 | E6: 1
A7: HealthPlus | B7: 0.55808656 | C7: 0.29954442 | D7: 0.14236902 | E7: 1
A8: Grand Total | B8: 0.57342857 | C8: 0.28742857 | D8: 0.13914286 | E8: 1

Sheet Cost vs Ticket Description
A3: Row Labels | B3: Sum of Cost_Estimate_USD - Clean
A4: Billing Issue | B4: 35250
A5: Long Wait Time | B5: 29390
A6: Need Help | B6: 28090 | F6: Row Labels | G6: Count of Ticket_ID_Clean | H6: Average of Cost_Estimate_USD - Clean
A7: Poor Service | B7: 7910 | F7: Billing Issue | G7: 855 | H7: 41.22807
A8: Service Delay | B8: 7470 | F8: Doctor Did Not Attend | G8: 176 | H8: 41.306818
A9: Doctor No Show | B9: 7270 | F9: Long Wait Time | G9: 711 | H9: 41.336146
A10: Grand Total | B10: 115380 | F10: Need Help | G10: 685 | H10: 41.007299
F11: Poor Service | G11: 172 | H11: 45.988372
F12: Service Delay | G12: 176 | H12: 42.443182
F13: Grand Total | G13: 2775 | H13: 41.578378

Sheet Resolution Time Satisfaction
A1: Resolution_Time_Analysis | B1: (Multiple Items)
A3: Count of Ticket_ID_Clean | B3: Column Labels
A4: Row Labels | B4: Good | C4: Bad | D4: Neutral | E4: Grand Total
A5: ≤4 hrs | B5: 0.55254237 | C5: 0.28813559 | D5: 0.15932203 | E5: 1
A6: 25–48 hrs | B6: 0.61754386 | C6: 0.27368421 | D6: 0.10877193 | E6: 1
A7: 5–8 hrs | B7: 0.60069444 | C7: 0.29861111 | D7: 0.10069444 | E7: 1
A8: 9–24 hrs | B8: 0.55956679 | C8: 0.33212996 | D8: 0.10830325 | E8: 1
A9: Grand Total | B9: 0.58253275 | C9: 0.29781659 | D9: 0.11965066 | E9: 1

Sheet First Repsonse Statisfaction
A1: Resolution_Time_Analysis | B1: (Multiple Items)
A3: Count of Ticket_ID_Clean | B3: Column Labels
A4: Row Labels | B4: ≤4 hrs | C4: 25–48 hrs | D4: 5–8 hrs | E4: 9–24 hrs | F4: Grand Total
A5: Low | B5: 0.26845638 | C5: 0.26845638 | D5: 0.23489933 | E5: 0.22818792 | F5: 1
A6: High | B6: 0.2739726 | C6: 0.23630137 | D6: 0.23287671 | E6: 0.25684932 | F6: 1
A7: Critical | B7: 0.25373134 | C7: 0.24253731 | D7: 0.2238806 | E7: 0.27985075 | F7: 1
A8: Medium | B8: 0.23344948 | C8: 0.24738676 | D8: 0.31358885 | E8: 0.20557491 | F8: 1
A9: Grand Total | B9: 0.25764192 | C9: 0.2489083 | D9: 0.25152838 | E9: 0.2419214 | F9: 1

Sheet Ticket Channel Description
A3: Count of Ticket_ID_Clean | B3: Column Labels
A4: Row Labels | B4: Billing Issue | C4: Long Wait Time | D4: Need Help | E4: Doctor Did Not Attend | F4: Service Delay | G4: Poor Service | H4: Grand Total
A5: Email | B5: 0.065225225 | C5: 0.053693694 | D5: 0.053333333 | E5: 0.011171171 | F5: 0.01045045 | G5: 0.011891892 | H5: 0.20576577
A6: Phone | B6: 0.061261261 | C6: 0.046126126 | D6: 0.052612613 | E6: 0.012612613 | F6: 0.01045045 | G6: 0.012612613 | H6: 0.19567568
A7: Walk-in | B7: 0.058738739 | C7: 0.048288288 | D7: 0.049009009 | E7: 0.014774775 | F7: 0.015135135 | G7: 0.012612613 | H7: 0.19855856
A8: Web | B8: 0.060900901 | C8: 0.052252252 | D8: 0.044324324 | E8: 0.013333333 | F8: 0.018378378 | G8: 0.011891892 | H8: 0.20108108
A9: WhatsApp | B9: 0.061981982 | C9: 0.055855856 | D9: 0.047567568 | E9: 0.011531532 | F9: 0.009009009 | G9: 0.012972973 | H9: 0.19891892
A10: Grand Total | B10: 0.30810811 | C10: 0.25621622 | D10: 0.24684685 | E10: 0.063423423 | F10: 0.063423423 | G10: 0.061981982 | H10: 1

Sheet Priority Satisfaction
A3: Count of Ticket_ID_Clean | B3: Column Labels
A4: Row Labels | B4: Good | C4: Bad | D4: Neutral | E4: Grand Total
A5: Low | B5: 0.59677419 | C5: 0.27419355 | D5: 0.12903226 | E5: 1
A6: High | B6: 0.57777778 | C6: 0.29590643 | D6: 0.12631579 | E6: 1
A7: Critical | B7: 0.56164384 | C7: 0.2956621 | D7: 0.14269406 | E7: 1
A8: Medium | B8: 0.55826859 | C8: 0.28412875 | D8: 0.15760266 | E8: 1
A9: Grand Total | B9: 0.57342857 | C9: 0.28742857 | D9: 0.13914286 | E9: 1

Sheet Age Tickets Description
A3: Count of Ticket_ID_Clean | B3: Column Labels
A4: Row Labels | B4: Billing Issue | C4: Doctor Did Not Attend | D4: Long Wait Time | E4: Need Help | F4: Poor Service | G4: Service Delay | H4: Grand Total
A5: 18–35 | B5: 0.31135531 | C5: 0.053113553 | D5: 0.24908425 | E5: 0.26923077 | F5: 0.058608059 | G5: 0.058608059 | H5: 1
A6: 0–17 | B6: 0.29189189 | C6: 0.075675676 | D6: 0.25945946 | E6: 0.25405405 | F6: 0.064864865 | G6: 0.054054054 | H6: 1
A7: 51–65 | B7: 0.31515152 | C7: 0.084848485 | D7: 0.2969697 | E7: 0.18787879 | F7: 0.048484848 | G7: 0.066666667 | H7: 1
A8: 36–50 | B8: 0.32236842 | C8: 0.078947368 | D8: 0.27631579 | E8: 0.21052632 | F8: 0.078947368 | G8: 0.032894737 | H8: 1
A9: 66+ | B9: 0.36575875 | C9: 0.042801556 | D9: 0.21400778 | E9: 0.25291829 | F9: 0.058365759 | G9: 0.06614786 | H9: 1
A10: Grand Total | B10: 0.31820637 | C10: 0.058887088 | D10: 0.25175581 | E10: 0.25337655 | F10: 0.059967585 | G10: 0.057806591 | H10: 1

Sheet Gender Ticket Description
A3: Count of Ticket_ID_Clean | B3: Column Labels
A4: Row Labels | B4: Billing Issue | C4: Long Wait Time | D4: Need Help | E4: Doctor Did Not Attend | F4: Service Delay | G4: Poor Service | H4: Grand Total
A5: Female | B5: 0.3090053 | C5: 0.25191289 | D5: 0.24602707 | E5: 0.066509712 | F5: 0.062978222 | G5: 0.063566804 | H5: 1
A6: Male | B6: 0.30669145 | C6: 0.26301115 | D6: 0.24814126 | E6: 0.058550186 | F6: 0.064126394 | G6: 0.059479554 | H6: 1
A7: Grand Total | B7: 0.30810811 | C7: 0.25621622 | D7: 0.24684685 | E7: 0.063423423 | F7: 0.063423423 | G7: 0.061981982 | H7: 1

Sheet Staisfaction by issues
A3: Count of Ticket_ID_Clean | B3: Column Labels
A4: Row Labels | B4: Bad | C4: Good | D4: Neutral | E4: Grand Total
A5: Billing Issue | B5: 0.28187135 | C5: 0.59181287 | D5: 0.12631579 | E5: 1
A6: Long Wait Time | B6: 0.302391 | C6: 0.5625879 | D6: 0.1350211 | E6: 1
A7: Need Help | B7: 0.28759124 | C7: 0.5620438 | D7: 0.15036496 | E7: 1
A8: Doctor Did Not Attend | B8: 0.34090909 | C8: 0.53977273 | D8: 0.11931818 | E8: 1
A9: Poor Service | B9: 0.27906977 | C9: 0.56976744 | D9: 0.15116279 | E9: 1
A10: Service Delay | B10: 0.25 | C10: 0.60227273 | D10: 0.14772727 | E10: 1
A11: Grand Total | B11: 0.29009009 | C11: 0.57297297 | D11: 0.13693694 | E11: 1
